{"uid":"88a4b8726b7a6190","name":"test_rpc_method_is_available[Test for Myriad, url: wss://gateway.mainnet.octopus.network/myriad/a4cb0a6e30ff5233a3567eb4e8cb71e0]","fullName":"tests.test_rpc_methods_availability#test_rpc_method_is_available","historyId":"10f1bafab6fa1e09515e87c5baf81252","time":{"start":1738681737774,"stop":1738681737774,"duration":0},"status":"broken","statusMessage":"ssl.SSLEOFError: [SSL: UNEXPECTED_EOF_WHILE_READING] EOF occurred in violation of protocol (_ssl.c:1000)","statusTrace":"request = <SubRequest 'connection_by_url' for <Function test_rpc_method_is_available[Test for Myriad, url: wss://gateway.mainnet.octopus.network/myriad/a4cb0a6e30ff5233a3567eb4e8cb71e0]>>\n\n    @pytest.fixture(scope=\"module\", params=collect_nodes_for_chains(get_substrate_chains()), ids=task_ids)\n    def connection_by_url(request):\n        data = request.param\n>       connection = execute_with_timeout(\n            timeout=FIXTURE_TIMEOUT,\n            function=create_connection_by_url,\n            args=(data[\"url\"],),\n            error_message=f'Timeout {FIXTURE_TIMEOUT} when creating connection: {data[\"url\"]}'\n        )\n\ntests/conftest.py:57: \n_ _ _ _ _ _ _ _ _ _ _ _ _ _ _ _ _ _ _ _ _ _ _ _ _ _ _ _ _ _ _ _ _ _ _ _ _ _ _ _ \ntests/conftest.py:32: in execute_with_timeout\n    return func_timeout(timeout=timeout, func=function, args=args)\n.venv/lib/python3.12/site-packages/func_timeout/dafunc.py:108: in func_timeout\n    raise_exception(exception)\n.venv/lib/python3.12/site-packages/func_timeout/py3_raise.py:7: in raise_exception\n    raise exception[0] from None\nscripts/utils/substrate_interface.py:30: in create_connection_by_url\n    substrate = SubstrateInterface(\n.venv/lib/python3.12/site-packages/substrateinterface/base.py:132: in __init__\n    self.connect_websocket()\n.venv/lib/python3.12/site-packages/substrateinterface/base.py:177: in connect_websocket\n    self.websocket = create_connection(\n.venv/lib/python3.12/site-packages/websocket/_core.py:646: in create_connection\n    websock.connect(url, **options)\n.venv/lib/python3.12/site-packages/websocket/_core.py:256: in connect\n    self.sock, addrs = connect(\n.venv/lib/python3.12/site-packages/websocket/_http.py:147: in connect\n    sock = _ssl_socket(sock, options.sslopt, hostname)\n.venv/lib/python3.12/site-packages/websocket/_http.py:307: in _ssl_socket\n    sock = _wrap_sni_socket(sock, sslopt, hostname, check_hostname)\n.venv/lib/python3.12/site-packages/websocket/_http.py:277: in _wrap_sni_socket\n    return context.wrap_socket(\n/usr/lib/python3.12/ssl.py:455: in wrap_socket\n    return self.sslsocket_class._create(\n/usr/lib/python3.12/ssl.py:1042: in _create\n    self.do_handshake()\n_ _ _ _ _ _ _ _ _ _ _ _ _ _ _ _ _ _ _ _ _ _ _ _ _ _ _ _ _ _ _ _ _ _ _ _ _ _ _ _ \n\nself = <ssl.SSLSocket [closed] fd=-1, family=2, type=1, proto=6>, block = False\n\n    @_sslcopydoc\n    def do_handshake(self, block=False):\n        self._check_connected()\n        timeout = self.gettimeout()\n        try:\n            if timeout == 0.0 and block:\n                self.settimeout(None)\n>           self._sslobj.do_handshake()\nE           ssl.SSLEOFError: [SSL: UNEXPECTED_EOF_WHILE_READING] EOF occurred in violation of protocol (_ssl.c:1000)\n\n/usr/lib/python3.12/ssl.py:1320: SSLEOFError","flaky":false,"newFailed":false,"newBroken":false,"newPassed":false,"retriesCount":0,"retriesStatusChange":false,"beforeStages":[{"name":"connection_by_url","time":{"start":1738681732399,"stop":1738681732677,"duration":278},"status":"broken","statusMessage":"ssl.SSLEOFError: [SSL: UNEXPECTED_EOF_WHILE_READING] EOF occurred in violation of protocol (_ssl.c:1000)\n","statusTrace":"  File \"/home/runner/work/test-runner/test-runner/nova-utils/.venv/lib/python3.12/site-packages/pluggy/_callers.py\", line 77, in _multicall\n    res = hook_impl.function(*args)\n          ^^^^^^^^^^^^^^^^^^^^^^^^^\n  File \"/home/runner/work/test-runner/test-runner/nova-utils/.venv/lib/python3.12/site-packages/_pytest/fixtures.py\", line 1128, in pytest_fixture_setup\n    result = call_fixture_func(fixturefunc, request, kwargs)\n             ^^^^^^^^^^^^^^^^^^^^^^^^^^^^^^^^^^^^^^^^^^^^^^^\n  File \"/home/runner/work/test-runner/test-runner/nova-utils/.venv/lib/python3.12/site-packages/_pytest/fixtures.py\", line 907, in call_fixture_func\n    fixture_result = fixturefunc(**kwargs)\n                     ^^^^^^^^^^^^^^^^^^^^^\n  File \"/home/runner/work/test-runner/test-runner/nova-utils/tests/conftest.py\", line 57, in connection_by_url\n    connection = execute_with_timeout(\n                 ^^^^^^^^^^^^^^^^^^^^^\n  File \"/home/runner/work/test-runner/test-runner/nova-utils/tests/conftest.py\", line 32, in execute_with_timeout\n    return func_timeout(timeout=timeout, func=function, args=args)\n           ^^^^^^^^^^^^^^^^^^^^^^^^^^^^^^^^^^^^^^^^^^^^^^^^^^^^^^^\n  File \"/home/runner/work/test-runner/test-runner/nova-utils/.venv/lib/python3.12/site-packages/func_timeout/dafunc.py\", line 108, in func_timeout\n    raise_exception(exception)\n  File \"/home/runner/work/test-runner/test-runner/nova-utils/.venv/lib/python3.12/site-packages/func_timeout/py3_raise.py\", line 7, in raise_exception\n    raise exception[0] from None\n  File \"/home/runner/work/test-runner/test-runner/nova-utils/scripts/utils/substrate_interface.py\", line 30, in create_connection_by_url\n    substrate = SubstrateInterface(\n                ^^^^^^^^^^^^^^^^^^^\n  File \"/home/runner/work/test-runner/test-runner/nova-utils/.venv/lib/python3.12/site-packages/substrateinterface/base.py\", line 132, in __init__\n    self.connect_websocket()\n  File \"/home/runner/work/test-runner/test-runner/nova-utils/.venv/lib/python3.12/site-packages/substrateinterface/base.py\", line 177, in connect_websocket\n    self.websocket = create_connection(\n                     ^^^^^^^^^^^^^^^^^^\n  File \"/home/runner/work/test-runner/test-runner/nova-utils/.venv/lib/python3.12/site-packages/websocket/_core.py\", line 646, in create_connection\n    websock.connect(url, **options)\n  File \"/home/runner/work/test-runner/test-runner/nova-utils/.venv/lib/python3.12/site-packages/websocket/_core.py\", line 256, in connect\n    self.sock, addrs = connect(\n                       ^^^^^^^^\n  File \"/home/runner/work/test-runner/test-runner/nova-utils/.venv/lib/python3.12/site-packages/websocket/_http.py\", line 147, in connect\n    sock = _ssl_socket(sock, options.sslopt, hostname)\n           ^^^^^^^^^^^^^^^^^^^^^^^^^^^^^^^^^^^^^^^^^^^\n  File \"/home/runner/work/test-runner/test-runner/nova-utils/.venv/lib/python3.12/site-packages/websocket/_http.py\", line 307, in _ssl_socket\n    sock = _wrap_sni_socket(sock, sslopt, hostname, check_hostname)\n           ^^^^^^^^^^^^^^^^^^^^^^^^^^^^^^^^^^^^^^^^^^^^^^^^^^^^^^^^\n  File \"/home/runner/work/test-runner/test-runner/nova-utils/.venv/lib/python3.12/site-packages/websocket/_http.py\", line 277, in _wrap_sni_socket\n    return context.wrap_socket(\n           ^^^^^^^^^^^^^^^^^^^^\n  File \"/usr/lib/python3.12/ssl.py\", line 455, in wrap_socket\n    return self.sslsocket_class._create(\n           ^^^^^^^^^^^^^^^^^^^^^^^^^^^^^\n  File \"/usr/lib/python3.12/ssl.py\", line 1042, in _create\n    self.do_handshake()\n  File \"/usr/lib/python3.12/ssl.py\", line 1320, in do_handshake\n    self._sslobj.do_handshake()\n","steps":[],"attachments":[],"parameters":[],"shouldDisplayMessage":true,"stepsCount":0,"attachmentsCount":0,"hasContent":true,"attachmentStep":false},{"name":"connection_by_url","time":{"start":1738681737775,"stop":1738681738181,"duration":406},"status":"broken","statusMessage":"ssl.SSLEOFError: [SSL: UNEXPECTED_EOF_WHILE_READING] EOF occurred in violation of protocol (_ssl.c:1000)\n","statusTrace":"  File \"/home/runner/work/test-runner/test-runner/nova-utils/.venv/lib/python3.12/site-packages/pluggy/_callers.py\", line 77, in _multicall\n    res = hook_impl.function(*args)\n          ^^^^^^^^^^^^^^^^^^^^^^^^^\n  File \"/home/runner/work/test-runner/test-runner/nova-utils/.venv/lib/python3.12/site-packages/_pytest/fixtures.py\", line 1128, in pytest_fixture_setup\n    result = call_fixture_func(fixturefunc, request, kwargs)\n             ^^^^^^^^^^^^^^^^^^^^^^^^^^^^^^^^^^^^^^^^^^^^^^^\n  File \"/home/runner/work/test-runner/test-runner/nova-utils/.venv/lib/python3.12/site-packages/_pytest/fixtures.py\", line 907, in call_fixture_func\n    fixture_result = fixturefunc(**kwargs)\n                     ^^^^^^^^^^^^^^^^^^^^^\n  File \"/home/runner/work/test-runner/test-runner/nova-utils/tests/conftest.py\", line 57, in connection_by_url\n    connection = execute_with_timeout(\n                 ^^^^^^^^^^^^^^^^^^^^^\n  File \"/home/runner/work/test-runner/test-runner/nova-utils/tests/conftest.py\", line 32, in execute_with_timeout\n    return func_timeout(timeout=timeout, func=function, args=args)\n           ^^^^^^^^^^^^^^^^^^^^^^^^^^^^^^^^^^^^^^^^^^^^^^^^^^^^^^^\n  File \"/home/runner/work/test-runner/test-runner/nova-utils/.venv/lib/python3.12/site-packages/func_timeout/dafunc.py\", line 108, in func_timeout\n    raise_exception(exception)\n  File \"/home/runner/work/test-runner/test-runner/nova-utils/.venv/lib/python3.12/site-packages/func_timeout/py3_raise.py\", line 7, in raise_exception\n    raise exception[0] from None\n  File \"/home/runner/work/test-runner/test-runner/nova-utils/scripts/utils/substrate_interface.py\", line 30, in create_connection_by_url\n    substrate = SubstrateInterface(\n                ^^^^^^^^^^^^^^^^^^^\n  File \"/home/runner/work/test-runner/test-runner/nova-utils/.venv/lib/python3.12/site-packages/substrateinterface/base.py\", line 132, in __init__\n    self.connect_websocket()\n  File \"/home/runner/work/test-runner/test-runner/nova-utils/.venv/lib/python3.12/site-packages/substrateinterface/base.py\", line 177, in connect_websocket\n    self.websocket = create_connection(\n                     ^^^^^^^^^^^^^^^^^^\n  File \"/home/runner/work/test-runner/test-runner/nova-utils/.venv/lib/python3.12/site-packages/websocket/_core.py\", line 646, in create_connection\n    websock.connect(url, **options)\n  File \"/home/runner/work/test-runner/test-runner/nova-utils/.venv/lib/python3.12/site-packages/websocket/_core.py\", line 256, in connect\n    self.sock, addrs = connect(\n                       ^^^^^^^^\n  File \"/home/runner/work/test-runner/test-runner/nova-utils/.venv/lib/python3.12/site-packages/websocket/_http.py\", line 147, in connect\n    sock = _ssl_socket(sock, options.sslopt, hostname)\n           ^^^^^^^^^^^^^^^^^^^^^^^^^^^^^^^^^^^^^^^^^^^\n  File \"/home/runner/work/test-runner/test-runner/nova-utils/.venv/lib/python3.12/site-packages/websocket/_http.py\", line 307, in _ssl_socket\n    sock = _wrap_sni_socket(sock, sslopt, hostname, check_hostname)\n           ^^^^^^^^^^^^^^^^^^^^^^^^^^^^^^^^^^^^^^^^^^^^^^^^^^^^^^^^\n  File \"/home/runner/work/test-runner/test-runner/nova-utils/.venv/lib/python3.12/site-packages/websocket/_http.py\", line 277, in _wrap_sni_socket\n    return context.wrap_socket(\n           ^^^^^^^^^^^^^^^^^^^^\n  File \"/usr/lib/python3.12/ssl.py\", line 455, in wrap_socket\n    return self.sslsocket_class._create(\n           ^^^^^^^^^^^^^^^^^^^^^^^^^^^^^\n  File \"/usr/lib/python3.12/ssl.py\", line 1042, in _create\n    self.do_handshake()\n  File \"/usr/lib/python3.12/ssl.py\", line 1320, in do_handshake\n    self._sslobj.do_handshake()\n","steps":[],"attachments":[],"parameters":[],"shouldDisplayMessage":true,"stepsCount":0,"attachmentsCount":0,"hasContent":true,"attachmentStep":false},{"name":"connection_by_url","time":{"start":1738681743324,"stop":1738681743588,"duration":264},"status":"broken","statusMessage":"ssl.SSLEOFError: [SSL: UNEXPECTED_EOF_WHILE_READING] EOF occurred in violation of protocol (_ssl.c:1000)\n","statusTrace":"  File \"/home/runner/work/test-runner/test-runner/nova-utils/.venv/lib/python3.12/site-packages/pluggy/_callers.py\", line 77, in _multicall\n    res = hook_impl.function(*args)\n          ^^^^^^^^^^^^^^^^^^^^^^^^^\n  File \"/home/runner/work/test-runner/test-runner/nova-utils/.venv/lib/python3.12/site-packages/_pytest/fixtures.py\", line 1128, in pytest_fixture_setup\n    result = call_fixture_func(fixturefunc, request, kwargs)\n             ^^^^^^^^^^^^^^^^^^^^^^^^^^^^^^^^^^^^^^^^^^^^^^^\n  File \"/home/runner/work/test-runner/test-runner/nova-utils/.venv/lib/python3.12/site-packages/_pytest/fixtures.py\", line 907, in call_fixture_func\n    fixture_result = fixturefunc(**kwargs)\n                     ^^^^^^^^^^^^^^^^^^^^^\n  File \"/home/runner/work/test-runner/test-runner/nova-utils/tests/conftest.py\", line 57, in connection_by_url\n    connection = execute_with_timeout(\n                 ^^^^^^^^^^^^^^^^^^^^^\n  File \"/home/runner/work/test-runner/test-runner/nova-utils/tests/conftest.py\", line 32, in execute_with_timeout\n    return func_timeout(timeout=timeout, func=function, args=args)\n           ^^^^^^^^^^^^^^^^^^^^^^^^^^^^^^^^^^^^^^^^^^^^^^^^^^^^^^^\n  File \"/home/runner/work/test-runner/test-runner/nova-utils/.venv/lib/python3.12/site-packages/func_timeout/dafunc.py\", line 108, in func_timeout\n    raise_exception(exception)\n  File \"/home/runner/work/test-runner/test-runner/nova-utils/.venv/lib/python3.12/site-packages/func_timeout/py3_raise.py\", line 7, in raise_exception\n    raise exception[0] from None\n  File \"/home/runner/work/test-runner/test-runner/nova-utils/scripts/utils/substrate_interface.py\", line 30, in create_connection_by_url\n    substrate = SubstrateInterface(\n                ^^^^^^^^^^^^^^^^^^^\n  File \"/home/runner/work/test-runner/test-runner/nova-utils/.venv/lib/python3.12/site-packages/substrateinterface/base.py\", line 132, in __init__\n    self.connect_websocket()\n  File \"/home/runner/work/test-runner/test-runner/nova-utils/.venv/lib/python3.12/site-packages/substrateinterface/base.py\", line 177, in connect_websocket\n    self.websocket = create_connection(\n                     ^^^^^^^^^^^^^^^^^^\n  File \"/home/runner/work/test-runner/test-runner/nova-utils/.venv/lib/python3.12/site-packages/websocket/_core.py\", line 646, in create_connection\n    websock.connect(url, **options)\n  File \"/home/runner/work/test-runner/test-runner/nova-utils/.venv/lib/python3.12/site-packages/websocket/_core.py\", line 256, in connect\n    self.sock, addrs = connect(\n                       ^^^^^^^^\n  File \"/home/runner/work/test-runner/test-runner/nova-utils/.venv/lib/python3.12/site-packages/websocket/_http.py\", line 147, in connect\n    sock = _ssl_socket(sock, options.sslopt, hostname)\n           ^^^^^^^^^^^^^^^^^^^^^^^^^^^^^^^^^^^^^^^^^^^\n  File \"/home/runner/work/test-runner/test-runner/nova-utils/.venv/lib/python3.12/site-packages/websocket/_http.py\", line 307, in _ssl_socket\n    sock = _wrap_sni_socket(sock, sslopt, hostname, check_hostname)\n           ^^^^^^^^^^^^^^^^^^^^^^^^^^^^^^^^^^^^^^^^^^^^^^^^^^^^^^^^\n  File \"/home/runner/work/test-runner/test-runner/nova-utils/.venv/lib/python3.12/site-packages/websocket/_http.py\", line 277, in _wrap_sni_socket\n    return context.wrap_socket(\n           ^^^^^^^^^^^^^^^^^^^^\n  File \"/usr/lib/python3.12/ssl.py\", line 455, in wrap_socket\n    return self.sslsocket_class._create(\n           ^^^^^^^^^^^^^^^^^^^^^^^^^^^^^\n  File \"/usr/lib/python3.12/ssl.py\", line 1042, in _create\n    self.do_handshake()\n  File \"/usr/lib/python3.12/ssl.py\", line 1320, in do_handshake\n    self._sslobj.do_handshake()\n","steps":[],"attachments":[],"parameters":[],"shouldDisplayMessage":true,"stepsCount":0,"attachmentsCount":0,"hasContent":true,"attachmentStep":false}],"testStage":{"status":"broken","statusMessage":"ssl.SSLEOFError: [SSL: UNEXPECTED_EOF_WHILE_READING] EOF occurred in violation of protocol (_ssl.c:1000)","statusTrace":"request = <SubRequest 'connection_by_url' for <Function test_rpc_method_is_available[Test for Myriad, url: wss://gateway.mainnet.octopus.network/myriad/a4cb0a6e30ff5233a3567eb4e8cb71e0]>>\n\n    @pytest.fixture(scope=\"module\", params=collect_nodes_for_chains(get_substrate_chains()), ids=task_ids)\n    def connection_by_url(request):\n        data = request.param\n>       connection = execute_with_timeout(\n            timeout=FIXTURE_TIMEOUT,\n            function=create_connection_by_url,\n            args=(data[\"url\"],),\n            error_message=f'Timeout {FIXTURE_TIMEOUT} when creating connection: {data[\"url\"]}'\n        )\n\ntests/conftest.py:57: \n_ _ _ _ _ _ _ _ _ _ _ _ _ _ _ _ _ _ _ _ _ _ _ _ _ _ _ _ _ _ _ _ _ _ _ _ _ _ _ _ \ntests/conftest.py:32: in execute_with_timeout\n    return func_timeout(timeout=timeout, func=function, args=args)\n.venv/lib/python3.12/site-packages/func_timeout/dafunc.py:108: in func_timeout\n    raise_exception(exception)\n.venv/lib/python3.12/site-packages/func_timeout/py3_raise.py:7: in raise_exception\n    raise exception[0] from None\nscripts/utils/substrate_interface.py:30: in create_connection_by_url\n    substrate = SubstrateInterface(\n.venv/lib/python3.12/site-packages/substrateinterface/base.py:132: in __init__\n    self.connect_websocket()\n.venv/lib/python3.12/site-packages/substrateinterface/base.py:177: in connect_websocket\n    self.websocket = create_connection(\n.venv/lib/python3.12/site-packages/websocket/_core.py:646: in create_connection\n    websock.connect(url, **options)\n.venv/lib/python3.12/site-packages/websocket/_core.py:256: in connect\n    self.sock, addrs = connect(\n.venv/lib/python3.12/site-packages/websocket/_http.py:147: in connect\n    sock = _ssl_socket(sock, options.sslopt, hostname)\n.venv/lib/python3.12/site-packages/websocket/_http.py:307: in _ssl_socket\n    sock = _wrap_sni_socket(sock, sslopt, hostname, check_hostname)\n.venv/lib/python3.12/site-packages/websocket/_http.py:277: in _wrap_sni_socket\n    return context.wrap_socket(\n/usr/lib/python3.12/ssl.py:455: in wrap_socket\n    return self.sslsocket_class._create(\n/usr/lib/python3.12/ssl.py:1042: in _create\n    self.do_handshake()\n_ _ _ _ _ _ _ _ _ _ _ _ _ _ _ _ _ _ _ _ _ _ _ _ _ _ _ _ _ _ _ _ _ _ _ _ _ _ _ _ \n\nself = <ssl.SSLSocket [closed] fd=-1, family=2, type=1, proto=6>, block = False\n\n    @_sslcopydoc\n    def do_handshake(self, block=False):\n        self._check_connected()\n        timeout = self.gettimeout()\n        try:\n            if timeout == 0.0 and block:\n                self.settimeout(None)\n>           self._sslobj.do_handshake()\nE           ssl.SSLEOFError: [SSL: UNEXPECTED_EOF_WHILE_READING] EOF occurred in violation of protocol (_ssl.c:1000)\n\n/usr/lib/python3.12/ssl.py:1320: SSLEOFError","steps":[],"attachments":[{"uid":"1f4fe193a156f274","name":"stdout","source":"1f4fe193a156f274.txt","type":"text/plain","size":432}],"parameters":[],"shouldDisplayMessage":true,"stepsCount":0,"attachmentsCount":1,"hasContent":true,"attachmentStep":false},"afterStages":[],"labels":[{"name":"parentSuite","value":"tests"},{"name":"suite","value":"test_rpc_methods_availability"},{"name":"host","value":"fv-az1911-92"},{"name":"thread","value":"5188-MainThread"},{"name":"framework","value":"pytest"},{"name":"language","value":"cpython3"},{"name":"package","value":"tests.test_rpc_methods_availability"},{"name":"resultFormat","value":"allure2"}],"parameters":[{"name":"connection_by_url","value":"{'url': 'wss://gateway.mainnet.octopus.network/myriad/a4cb0a6e30ff5233a3567eb4e8cb71e0', 'name': 'Myriad'}"}],"links":[],"hidden":true,"retry":true,"extra":{"categories":[],"tags":[]},"source":"88a4b8726b7a6190.json","parameterValues":["{'url': 'wss://gateway.mainnet.octopus.network/myriad/a4cb0a6e30ff5233a3567eb4e8cb71e0', 'name': 'Myriad'}"]}