{"uid":"1fcbc8825457373c","name":"test_rpc_method_is_available[Test for Robonomics, url: wss://robonomics.0xsamsara.com]","fullName":"tests.test_rpc_methods_availability#test_rpc_method_is_available","historyId":"4516f1d6e4ee4b390324950f43e35296","time":{"start":1729933523239,"stop":1729933523239,"duration":0},"status":"broken","statusMessage":"ConnectionRefusedError: [Errno 111] Connection refused","statusTrace":"request = <SubRequest 'connection_by_url' for <Function test_rpc_method_is_available[Test for Robonomics, url: wss://robonomics.0xsamsara.com]>>\n\n    @pytest.fixture(scope=\"module\", params=collect_nodes_for_chains(get_substrate_chains()), ids=task_ids)\n    def connection_by_url(request):\n        data = request.param\n>       connection = execute_with_timeout(\n            timeout=FIXTURE_TIMEOUT,\n            function=create_connection_by_url,\n            args=(data[\"url\"],),\n            error_message=f'Timeout {FIXTURE_TIMEOUT} when creating connection: {data[\"url\"]}'\n        )\n\ntests/conftest.py:57: \n_ _ _ _ _ _ _ _ _ _ _ _ _ _ _ _ _ _ _ _ _ _ _ _ _ _ _ _ _ _ _ _ _ _ _ _ _ _ _ _ \ntests/conftest.py:32: in execute_with_timeout\n    return func_timeout(timeout=timeout, func=function, args=args)\n.venv/lib/python3.10/site-packages/func_timeout/dafunc.py:108: in func_timeout\n    raise_exception(exception)\n.venv/lib/python3.10/site-packages/func_timeout/py3_raise.py:7: in raise_exception\n    raise exception[0] from None\nscripts/utils/substrate_interface.py:30: in create_connection_by_url\n    substrate = SubstrateInterface(\n.venv/lib/python3.10/site-packages/substrateinterface/base.py:132: in __init__\n    self.connect_websocket()\n.venv/lib/python3.10/site-packages/substrateinterface/base.py:177: in connect_websocket\n    self.websocket = create_connection(\n.venv/lib/python3.10/site-packages/websocket/_core.py:646: in create_connection\n    websock.connect(url, **options)\n.venv/lib/python3.10/site-packages/websocket/_core.py:256: in connect\n    self.sock, addrs = connect(\n.venv/lib/python3.10/site-packages/websocket/_http.py:141: in connect\n    sock = _open_socket(addrinfo_list, options.sockopt, options.timeout)\n.venv/lib/python3.10/site-packages/websocket/_http.py:228: in _open_socket\n    raise err\n_ _ _ _ _ _ _ _ _ _ _ _ _ _ _ _ _ _ _ _ _ _ _ _ _ _ _ _ _ _ _ _ _ _ _ _ _ _ _ _ \n\naddrinfo_list = [(<AddressFamily.AF_INET: 2>, <SocketKind.SOCK_STREAM: 1>, 6, '', ('212.227.151.235', 443))]\nsockopt = [], timeout = None\n\n    def _open_socket(addrinfo_list, sockopt, timeout):\n        err = None\n        for addrinfo in addrinfo_list:\n            family, socktype, proto = addrinfo[:3]\n            sock = socket.socket(family, socktype, proto)\n            sock.settimeout(timeout)\n            for opts in DEFAULT_SOCKET_OPTION:\n                sock.setsockopt(*opts)\n            for opts in sockopt:\n                sock.setsockopt(*opts)\n    \n            address = addrinfo[4]\n            err = None\n            while not err:\n                try:\n>                   sock.connect(address)\nE                   ConnectionRefusedError: [Errno 111] Connection refused\n\n.venv/lib/python3.10/site-packages/websocket/_http.py:205: ConnectionRefusedError","flaky":false,"newFailed":false,"newBroken":false,"newPassed":false,"retriesCount":2,"retriesStatusChange":false,"beforeStages":[{"name":"connection_by_url","time":{"start":1729933512231,"stop":1729933512496,"duration":265},"status":"broken","statusMessage":"ConnectionRefusedError: [Errno 111] Connection refused\n","statusTrace":"  File \"/home/runner/work/test-runner/test-runner/nova-utils/.venv/lib/python3.10/site-packages/pluggy/_callers.py\", line 77, in _multicall\n    res = hook_impl.function(*args)\n  File \"/home/runner/work/test-runner/test-runner/nova-utils/.venv/lib/python3.10/site-packages/_pytest/fixtures.py\", line 1128, in pytest_fixture_setup\n    result = call_fixture_func(fixturefunc, request, kwargs)\n  File \"/home/runner/work/test-runner/test-runner/nova-utils/.venv/lib/python3.10/site-packages/_pytest/fixtures.py\", line 907, in call_fixture_func\n    fixture_result = fixturefunc(**kwargs)\n  File \"/home/runner/work/test-runner/test-runner/nova-utils/tests/conftest.py\", line 57, in connection_by_url\n    connection = execute_with_timeout(\n  File \"/home/runner/work/test-runner/test-runner/nova-utils/tests/conftest.py\", line 32, in execute_with_timeout\n    return func_timeout(timeout=timeout, func=function, args=args)\n  File \"/home/runner/work/test-runner/test-runner/nova-utils/.venv/lib/python3.10/site-packages/func_timeout/dafunc.py\", line 108, in func_timeout\n    raise_exception(exception)\n  File \"/home/runner/work/test-runner/test-runner/nova-utils/.venv/lib/python3.10/site-packages/func_timeout/py3_raise.py\", line 7, in raise_exception\n    raise exception[0] from None\n  File \"/home/runner/work/test-runner/test-runner/nova-utils/scripts/utils/substrate_interface.py\", line 30, in create_connection_by_url\n    substrate = SubstrateInterface(\n  File \"/home/runner/work/test-runner/test-runner/nova-utils/.venv/lib/python3.10/site-packages/substrateinterface/base.py\", line 132, in __init__\n    self.connect_websocket()\n  File \"/home/runner/work/test-runner/test-runner/nova-utils/.venv/lib/python3.10/site-packages/substrateinterface/base.py\", line 177, in connect_websocket\n    self.websocket = create_connection(\n  File \"/home/runner/work/test-runner/test-runner/nova-utils/.venv/lib/python3.10/site-packages/websocket/_core.py\", line 646, in create_connection\n    websock.connect(url, **options)\n  File \"/home/runner/work/test-runner/test-runner/nova-utils/.venv/lib/python3.10/site-packages/websocket/_core.py\", line 256, in connect\n    self.sock, addrs = connect(\n  File \"/home/runner/work/test-runner/test-runner/nova-utils/.venv/lib/python3.10/site-packages/websocket/_http.py\", line 141, in connect\n    sock = _open_socket(addrinfo_list, options.sockopt, options.timeout)\n  File \"/home/runner/work/test-runner/test-runner/nova-utils/.venv/lib/python3.10/site-packages/websocket/_http.py\", line 228, in _open_socket\n    raise err\n  File \"/home/runner/work/test-runner/test-runner/nova-utils/.venv/lib/python3.10/site-packages/websocket/_http.py\", line 205, in _open_socket\n    sock.connect(address)\n","steps":[],"attachments":[],"parameters":[],"shouldDisplayMessage":true,"stepsCount":0,"attachmentsCount":0,"hasContent":true,"attachmentStep":false},{"name":"connection_by_url","time":{"start":1729933517594,"stop":1729933517885,"duration":291},"status":"broken","statusMessage":"ConnectionRefusedError: [Errno 111] Connection refused\n","statusTrace":"  File \"/home/runner/work/test-runner/test-runner/nova-utils/.venv/lib/python3.10/site-packages/pluggy/_callers.py\", line 77, in _multicall\n    res = hook_impl.function(*args)\n  File \"/home/runner/work/test-runner/test-runner/nova-utils/.venv/lib/python3.10/site-packages/_pytest/fixtures.py\", line 1128, in pytest_fixture_setup\n    result = call_fixture_func(fixturefunc, request, kwargs)\n  File \"/home/runner/work/test-runner/test-runner/nova-utils/.venv/lib/python3.10/site-packages/_pytest/fixtures.py\", line 907, in call_fixture_func\n    fixture_result = fixturefunc(**kwargs)\n  File \"/home/runner/work/test-runner/test-runner/nova-utils/tests/conftest.py\", line 57, in connection_by_url\n    connection = execute_with_timeout(\n  File \"/home/runner/work/test-runner/test-runner/nova-utils/tests/conftest.py\", line 32, in execute_with_timeout\n    return func_timeout(timeout=timeout, func=function, args=args)\n  File \"/home/runner/work/test-runner/test-runner/nova-utils/.venv/lib/python3.10/site-packages/func_timeout/dafunc.py\", line 108, in func_timeout\n    raise_exception(exception)\n  File \"/home/runner/work/test-runner/test-runner/nova-utils/.venv/lib/python3.10/site-packages/func_timeout/py3_raise.py\", line 7, in raise_exception\n    raise exception[0] from None\n  File \"/home/runner/work/test-runner/test-runner/nova-utils/scripts/utils/substrate_interface.py\", line 30, in create_connection_by_url\n    substrate = SubstrateInterface(\n  File \"/home/runner/work/test-runner/test-runner/nova-utils/.venv/lib/python3.10/site-packages/substrateinterface/base.py\", line 132, in __init__\n    self.connect_websocket()\n  File \"/home/runner/work/test-runner/test-runner/nova-utils/.venv/lib/python3.10/site-packages/substrateinterface/base.py\", line 177, in connect_websocket\n    self.websocket = create_connection(\n  File \"/home/runner/work/test-runner/test-runner/nova-utils/.venv/lib/python3.10/site-packages/websocket/_core.py\", line 646, in create_connection\n    websock.connect(url, **options)\n  File \"/home/runner/work/test-runner/test-runner/nova-utils/.venv/lib/python3.10/site-packages/websocket/_core.py\", line 256, in connect\n    self.sock, addrs = connect(\n  File \"/home/runner/work/test-runner/test-runner/nova-utils/.venv/lib/python3.10/site-packages/websocket/_http.py\", line 141, in connect\n    sock = _open_socket(addrinfo_list, options.sockopt, options.timeout)\n  File \"/home/runner/work/test-runner/test-runner/nova-utils/.venv/lib/python3.10/site-packages/websocket/_http.py\", line 228, in _open_socket\n    raise err\n  File \"/home/runner/work/test-runner/test-runner/nova-utils/.venv/lib/python3.10/site-packages/websocket/_http.py\", line 205, in _open_socket\n    sock.connect(address)\n","steps":[],"attachments":[],"parameters":[],"shouldDisplayMessage":true,"stepsCount":0,"attachmentsCount":0,"hasContent":true,"attachmentStep":false},{"name":"connection_by_url","time":{"start":1729933523239,"stop":1729933523530,"duration":291},"status":"broken","statusMessage":"ConnectionRefusedError: [Errno 111] Connection refused\n","statusTrace":"  File \"/home/runner/work/test-runner/test-runner/nova-utils/.venv/lib/python3.10/site-packages/pluggy/_callers.py\", line 77, in _multicall\n    res = hook_impl.function(*args)\n  File \"/home/runner/work/test-runner/test-runner/nova-utils/.venv/lib/python3.10/site-packages/_pytest/fixtures.py\", line 1128, in pytest_fixture_setup\n    result = call_fixture_func(fixturefunc, request, kwargs)\n  File \"/home/runner/work/test-runner/test-runner/nova-utils/.venv/lib/python3.10/site-packages/_pytest/fixtures.py\", line 907, in call_fixture_func\n    fixture_result = fixturefunc(**kwargs)\n  File \"/home/runner/work/test-runner/test-runner/nova-utils/tests/conftest.py\", line 57, in connection_by_url\n    connection = execute_with_timeout(\n  File \"/home/runner/work/test-runner/test-runner/nova-utils/tests/conftest.py\", line 32, in execute_with_timeout\n    return func_timeout(timeout=timeout, func=function, args=args)\n  File \"/home/runner/work/test-runner/test-runner/nova-utils/.venv/lib/python3.10/site-packages/func_timeout/dafunc.py\", line 108, in func_timeout\n    raise_exception(exception)\n  File \"/home/runner/work/test-runner/test-runner/nova-utils/.venv/lib/python3.10/site-packages/func_timeout/py3_raise.py\", line 7, in raise_exception\n    raise exception[0] from None\n  File \"/home/runner/work/test-runner/test-runner/nova-utils/scripts/utils/substrate_interface.py\", line 30, in create_connection_by_url\n    substrate = SubstrateInterface(\n  File \"/home/runner/work/test-runner/test-runner/nova-utils/.venv/lib/python3.10/site-packages/substrateinterface/base.py\", line 132, in __init__\n    self.connect_websocket()\n  File \"/home/runner/work/test-runner/test-runner/nova-utils/.venv/lib/python3.10/site-packages/substrateinterface/base.py\", line 177, in connect_websocket\n    self.websocket = create_connection(\n  File \"/home/runner/work/test-runner/test-runner/nova-utils/.venv/lib/python3.10/site-packages/websocket/_core.py\", line 646, in create_connection\n    websock.connect(url, **options)\n  File \"/home/runner/work/test-runner/test-runner/nova-utils/.venv/lib/python3.10/site-packages/websocket/_core.py\", line 256, in connect\n    self.sock, addrs = connect(\n  File \"/home/runner/work/test-runner/test-runner/nova-utils/.venv/lib/python3.10/site-packages/websocket/_http.py\", line 141, in connect\n    sock = _open_socket(addrinfo_list, options.sockopt, options.timeout)\n  File \"/home/runner/work/test-runner/test-runner/nova-utils/.venv/lib/python3.10/site-packages/websocket/_http.py\", line 228, in _open_socket\n    raise err\n  File \"/home/runner/work/test-runner/test-runner/nova-utils/.venv/lib/python3.10/site-packages/websocket/_http.py\", line 205, in _open_socket\n    sock.connect(address)\n","steps":[],"attachments":[],"parameters":[],"shouldDisplayMessage":true,"stepsCount":0,"attachmentsCount":0,"hasContent":true,"attachmentStep":false}],"testStage":{"status":"broken","statusMessage":"ConnectionRefusedError: [Errno 111] Connection refused","statusTrace":"request = <SubRequest 'connection_by_url' for <Function test_rpc_method_is_available[Test for Robonomics, url: wss://robonomics.0xsamsara.com]>>\n\n    @pytest.fixture(scope=\"module\", params=collect_nodes_for_chains(get_substrate_chains()), ids=task_ids)\n    def connection_by_url(request):\n        data = request.param\n>       connection = execute_with_timeout(\n            timeout=FIXTURE_TIMEOUT,\n            function=create_connection_by_url,\n            args=(data[\"url\"],),\n            error_message=f'Timeout {FIXTURE_TIMEOUT} when creating connection: {data[\"url\"]}'\n        )\n\ntests/conftest.py:57: \n_ _ _ _ _ _ _ _ _ _ _ _ _ _ _ _ _ _ _ _ _ _ _ _ _ _ _ _ _ _ _ _ _ _ _ _ _ _ _ _ \ntests/conftest.py:32: in execute_with_timeout\n    return func_timeout(timeout=timeout, func=function, args=args)\n.venv/lib/python3.10/site-packages/func_timeout/dafunc.py:108: in func_timeout\n    raise_exception(exception)\n.venv/lib/python3.10/site-packages/func_timeout/py3_raise.py:7: in raise_exception\n    raise exception[0] from None\nscripts/utils/substrate_interface.py:30: in create_connection_by_url\n    substrate = SubstrateInterface(\n.venv/lib/python3.10/site-packages/substrateinterface/base.py:132: in __init__\n    self.connect_websocket()\n.venv/lib/python3.10/site-packages/substrateinterface/base.py:177: in connect_websocket\n    self.websocket = create_connection(\n.venv/lib/python3.10/site-packages/websocket/_core.py:646: in create_connection\n    websock.connect(url, **options)\n.venv/lib/python3.10/site-packages/websocket/_core.py:256: in connect\n    self.sock, addrs = connect(\n.venv/lib/python3.10/site-packages/websocket/_http.py:141: in connect\n    sock = _open_socket(addrinfo_list, options.sockopt, options.timeout)\n.venv/lib/python3.10/site-packages/websocket/_http.py:228: in _open_socket\n    raise err\n_ _ _ _ _ _ _ _ _ _ _ _ _ _ _ _ _ _ _ _ _ _ _ _ _ _ _ _ _ _ _ _ _ _ _ _ _ _ _ _ \n\naddrinfo_list = [(<AddressFamily.AF_INET: 2>, <SocketKind.SOCK_STREAM: 1>, 6, '', ('212.227.151.235', 443))]\nsockopt = [], timeout = None\n\n    def _open_socket(addrinfo_list, sockopt, timeout):\n        err = None\n        for addrinfo in addrinfo_list:\n            family, socktype, proto = addrinfo[:3]\n            sock = socket.socket(family, socktype, proto)\n            sock.settimeout(timeout)\n            for opts in DEFAULT_SOCKET_OPTION:\n                sock.setsockopt(*opts)\n            for opts in sockopt:\n                sock.setsockopt(*opts)\n    \n            address = addrinfo[4]\n            err = None\n            while not err:\n                try:\n>                   sock.connect(address)\nE                   ConnectionRefusedError: [Errno 111] Connection refused\n\n.venv/lib/python3.10/site-packages/websocket/_http.py:205: ConnectionRefusedError","steps":[],"attachments":[{"uid":"19f306bf18c3b319","name":"stdout","source":"19f306bf18c3b319.txt","type":"text/plain","size":336}],"parameters":[],"shouldDisplayMessage":true,"stepsCount":0,"attachmentsCount":1,"hasContent":true,"attachmentStep":false},"afterStages":[],"labels":[{"name":"parentSuite","value":"tests"},{"name":"suite","value":"test_rpc_methods_availability"},{"name":"host","value":"fv-az1272-401"},{"name":"thread","value":"2204-MainThread"},{"name":"framework","value":"pytest"},{"name":"language","value":"cpython3"},{"name":"package","value":"tests.test_rpc_methods_availability"},{"name":"resultFormat","value":"allure2"}],"parameters":[{"name":"connection_by_url","value":"{'url': 'wss://robonomics.0xsamsara.com', 'name': 'Robonomics'}"}],"links":[],"hidden":false,"retry":false,"extra":{"severity":"normal","retries":[{"uid":"bf39a1a5b8a4579b","status":"broken","statusDetails":"ConnectionRefusedError: [Errno 111] Connection refused","time":{"start":1729933517594,"stop":1729933517594,"duration":0}},{"uid":"dad6573194c90193","status":"broken","statusDetails":"ConnectionRefusedError: [Errno 111] Connection refused","time":{"start":1729933512230,"stop":1729933512230,"duration":0}}],"categories":[{"name":"Test defects","matchedStatuses":[],"flaky":false}],"history":{"statistic":{"failed":0,"broken":16,"skipped":0,"passed":0,"unknown":0,"total":16},"items":[{"uid":"c345e567af09b32c","reportUrl":"https://novasamatech.github.io/test-runner/5791//#testresult/c345e567af09b32c","status":"broken","statusDetails":"ConnectionRefusedError: [Errno 111] Connection refused","time":{"start":1729868738149,"stop":1729868738149,"duration":0}},{"uid":"4e4d37218f3ae33b","reportUrl":"https://novasamatech.github.io/test-runner/5790//#testresult/4e4d37218f3ae33b","status":"broken","statusDetails":"ConnectionRefusedError: [Errno 111] Connection refused","time":{"start":1729847162288,"stop":1729847162288,"duration":0}},{"uid":"c46622842c46b82f","reportUrl":"https://novasamatech.github.io/test-runner/5789//#testresult/c46622842c46b82f","status":"broken","statusDetails":"ConnectionRefusedError: [Errno 111] Connection refused","time":{"start":1729782342126,"stop":1729782342126,"duration":0}},{"uid":"456410e6056d6ef7","reportUrl":"https://novasamatech.github.io/test-runner/5788//#testresult/456410e6056d6ef7","status":"broken","statusDetails":"ConnectionRefusedError: [Errno 111] Connection refused","time":{"start":1729760744146,"stop":1729760744146,"duration":0}},{"uid":"e5e58e8a64b00242","reportUrl":"https://novasamatech.github.io/test-runner/5787//#testresult/e5e58e8a64b00242","status":"broken","statusDetails":"ConnectionRefusedError: [Errno 111] Connection refused","time":{"start":1729695942789,"stop":1729695942789,"duration":0}},{"uid":"82fe73f0947eb92","reportUrl":"https://novasamatech.github.io/test-runner/5786//#testresult/82fe73f0947eb92","status":"broken","statusDetails":"ConnectionRefusedError: [Errno 111] Connection refused","time":{"start":1729674380881,"stop":1729674380881,"duration":0}},{"uid":"a08550f97169a2bc","reportUrl":"https://novasamatech.github.io/test-runner/5785//#testresult/a08550f97169a2bc","status":"broken","statusDetails":"ConnectionRefusedError: [Errno 111] Connection refused","time":{"start":1729609553917,"stop":1729609553917,"duration":0}},{"uid":"996679d7199c1e5d","reportUrl":"https://novasamatech.github.io/test-runner/5784//#testresult/996679d7199c1e5d","status":"broken","statusDetails":"ConnectionRefusedError: [Errno 111] Connection refused","time":{"start":1729587939554,"stop":1729587939554,"duration":0}},{"uid":"213694626dfa5e53","reportUrl":"https://novasamatech.github.io/test-runner/5783//#testresult/213694626dfa5e53","status":"broken","statusDetails":"ConnectionRefusedError: [Errno 111] Connection refused","time":{"start":1729523150149,"stop":1729523150149,"duration":0}},{"uid":"7060b534e49580b2","reportUrl":"https://novasamatech.github.io/test-runner/5776//#testresult/7060b534e49580b2","status":"broken","statusDetails":"ConnectionRefusedError: [Errno 111] Connection refused","time":{"start":1729242371785,"stop":1729242371785,"duration":0}},{"uid":"174277cdfeb75289","reportUrl":"https://novasamatech.github.io/test-runner/5775//#testresult/174277cdfeb75289","status":"broken","statusDetails":"ConnectionRefusedError: [Errno 111] Connection refused","time":{"start":1729177517190,"stop":1729177517190,"duration":0}},{"uid":"89db5bfd4a5285b0","reportUrl":"https://novasamatech.github.io/test-runner/5774//#testresult/89db5bfd4a5285b0","status":"broken","statusDetails":"ConnectionRefusedError: [Errno 111] Connection refused","time":{"start":1729155940970,"stop":1729155940970,"duration":0}},{"uid":"a5a13d33a21e8d10","reportUrl":"https://novasamatech.github.io/test-runner/5773//#testresult/a5a13d33a21e8d10","status":"broken","statusDetails":"ConnectionRefusedError: [Errno 111] Connection refused","time":{"start":1729091147768,"stop":1729091147768,"duration":0}},{"uid":"804187f09126bec2","reportUrl":"https://novasamatech.github.io/test-runner/5772//#testresult/804187f09126bec2","status":"broken","statusDetails":"ConnectionRefusedError: [Errno 111] Connection refused","time":{"start":1729069547126,"stop":1729069547126,"duration":0}},{"uid":"6b6cf83d9c23de8c","reportUrl":"https://novasamatech.github.io/test-runner/5771//#testresult/6b6cf83d9c23de8c","status":"broken","statusDetails":"ConnectionRefusedError: [Errno 111] Connection refused","time":{"start":1729004744567,"stop":1729004744567,"duration":0}}]},"tags":[]},"source":"1fcbc8825457373c.json","parameterValues":["{'url': 'wss://robonomics.0xsamsara.com', 'name': 'Robonomics'}"]}